<?xml version="1.0"?>
<robot name="roco_arm">
  <link name="base_link">
    <visual>
      <geometry>
        <cylinder length="0.051" radius="0.1"/>
      </geometry>
    </visual>
  </link>

  <link name="arm_turret">
    <visual>
      <geometry>
        <box size="0.064 0.064 0.035"/>
      </geometry>
      <origin rpy="0 0 0" xyz="0 0 0.0175" />
    </visual>
  </link>

  <link name="first_segment">
    <visual>
      <geometry>
        <box size="0.12 0.032 0.032"/>
      </geometry>
      <origin rpy="0 0 0" xyz="-0.06 0 0" />
    </visual>
  </link>

  <link name="second_segment">
    <visual>
      <geometry>
        <box size="0.068 0.032 0.032"/>
      </geometry>
      <origin rpy="0 0 0" xyz="-0.034 0 0" />
    </visual>
  </link>

 <joint name="turret_swivel" type="continuous">
    <axis xyz="0 0 1" />
    <parent link="base_link"/>
    <child link="arm_turret"/>
    <origin xyz="0 0 0.03" />
  </joint>

  <joint name="turret_to_first" type="revolute">
    <axis xyz="0 1 0" />
    <limit effort="1000" lower="0" upper="1.05" velocity="0.3" />
    <parent link="arm_turret"/>
    <child link="first_segment"/>
    <origin xyz="0 0 0.0255" />
  </joint>

<joint name="first_to_second" type="revolute">
    <axis xyz="0 1 0" />
    <limit effort="1000" lower="-1.57" upper="1.57" velocity="0.3" />
    <parent link="first_segment"/>
    <child link="second_segment"/>
    <origin xyz="-0.12 0 0" />
  </joint>

</robot>
